Workbook

Sheet Summary
A1: DO NOT UPDATE THE STATUS IN THIS SHEET. IT IS FORMULATED TO CAPTURE THE STATUS FROM OTHER SHEETS.
A2: Sheet # | B2: Test scenarios Covered | C2: Status (Inventor) | D2: Status (IC) | E2: Status (Admin)
A3: SYM_3.6_INV_1 | B3: 1.User should be able to create a draft invention disclosure. | C3: =SYM_3.6_INV_1!K20 | D3: =SYM_3.6_INV_1!L20 | E3: =SYM_3.6_INV_1!M20
A4: SYM_3.6_INV_1 | B4: 2.User should be able to edit the invention disclosure. | C4: =SYM_3.6_INV_1!K33 | D4: =SYM_3.6_INV_1!L33 | E4: =SYM_3.6_INV_1!M33
A5: SYM_3.6_INV_1 | B5: 3. User should be able to add and edit notes to the disclosure. | C5: =SYM_3.6_INV_1!K38 | D5: =SYM_3.6_INV_1!L38 | E5: =SYM_3.6_INV_1!M38
A6: SYM_3.6_INV_1 | B6: 4. User should be able to share the notes to an the disclosure. | C6: =SYM_3.6_INV_1!K48 | D6: =SYM_3.6_INV_1!L48 | E6: =SYM_3.6_INV_1!M48
A7: SYM_3.6_INV_1 | B7: 5. User should be able to upload files to the disclosure. | C7: =SYM_3.6_INV_1!K55 | D7: =SYM_3.6_INV_1!L55 | E7: =SYM_3.6_INV_1!M55
A8: SYM_3.6_INV_1 | B8: 6. User should be able to create Keywords for a disclosure. | C8: =SYM_3.6_INV_1!K61 | D8: =SYM_3.6_INV_1!L61 | E8: =SYM_3.6_INV_1!M61
A9: SYM_3.6_INV_1 | B9: 7. User should be able to add and remove additional Inventors to the disclosure. | C9: =SYM_3.6_INV_1!K65 | D9: =SYM_3.6_INV_1!L65 | E9: =SYM_3.6_INV_1!M65
A10: SYM_3.6_INV_1 | B10: 8. User should be able to Submit the invention disclosure. | C10: =SYM_3.6_INV_1!K73 | D10: =SYM_3.6_INV_1!L73 | E10: =SYM_3.6_INV_1!M73
A11: SYM_3.6_INV_1 | B11: 9. User should be able to edit the some of the disclosure information after submitting it. | C11: =SYM_3.6_INV_1!K76 | D11: =SYM_3.6_INV_1!L76 | E11: =SYM_3.6_INV_1!M76
A12: SYM_3.6_INV_2 | B12: 1. User should be able to view the Printable view of all the Invention disclosures accessed by them. | C12: =SYM_3.6_INV_2!K14 | D12: =SYM_3.6_INV_2!L14 | E12: =SYM_3.6_INV_2!M14
A13: SYM_3.6_INV_2 | B13: 2. User should be able to Reassign-IC to an Invention disclosure. | C13: =SYM_3.6_INV_2!K20 | D13: =SYM_3.6_INV_2!L20 | E13: =SYM_3.6_INV_2!M20
A14: SYM_3.6_INV_3 | B14: 1. User should be able to clone an Invention disclosure. | C14: NA | D14: =SYM_3.6_INV_3!K14 | E14: =SYM_3.6_INV_3!L14
A15: SYM_3.6_INV_3 | B15: 2. User should be able to delete an Invention disclosure. | C15: NA | D15: =SYM_3.6_INV_3!K21 | E15: =SYM_3.6_INV_3!L21
A16: SYM_3.6_INV_4 | B16: 1. User should be able to view the invention disclosures created in the Path associated to them. | C16: NA | D16: =SYM_3.6_INV_4!K16 | E16: =SYM_3.6_INV_4!L16
A17: SYM_3.6_INV_4 | B17: 2. User should be able to create a PRC Meeting for the invention disclosure. | C17: NA | D17: =SYM_3.6_INV_4!K20 | E17: =SYM_3.6_INV_4!L20
A18: SYM_3.6_INV_4 | B18: 3. User should be able to approve the information disclosure. | C18: NA | D18: =SYM_3.6_INV_4!K30 | E18: =SYM_3.6_INV_4!L30
A19: SYM_3.6_INV_4 | B19: 4. User should be able to approve and send the disclosure to OC . | C19: NA | D19: =SYM_3.6_INV_4!K41 | E19: =SYM_3.6_INV_4!L41
A20: SYM_3.6_INV_4 | B20: 5. User should be able to set disclosure to International Filing Decision. | C20: NA | D20: =SYM_3.6_INV_4!K55 | E20: =SYM_3.6_INV_4!L55
A21: SYM_3.6_INV_5 | B21: 1. IC User should be able to request for more information to the inventor. | C21: =SYM_3.6_INV_5!L16 -> NA | D21: =SYM_3.6_INV_5!K16
A22: SYM_3.6_INV_5 | B22: 2. Inventor should be able to respond to the RFI. | C22: =SYM_3.6_INV_5!L25 | D22: =SYM_3.6_INV_5!K25 -> NA
A23: SYM_3.6_INV_6 | B23: 1. User should be able to request for patent search for the disclosure. | C23: NA | D23: =SYM_3.6_INV_6!K16 | E23: =SYM_3.6_INV_6!L16
A24: SYM_3.6_INV_7 | B24: 1. User should be able to set the disclosure status as Hold. | C24: NA | D24: =SYM_3.6_INV_7!K16 | E24: =SYM_3.6_INV_7!L16
A25: SYM_3.6_INV_7 | B25: 2. User should be able to set the disclosure status as Reject. | C25: NA | D25: =SYM_3.6_INV_7!K25 | E25: =SYM_3.6_INV_7!L25
A26: SYM_3.6_INV_8 | B26: 1. User should be able to set disclosure as defensive publication. | C26: NA | D26: =SYM_3.6_INV_8!K16 | E26: =SYM_3.6_INV_8!L16
A27: SYM_3.6_INV_8 | B27: 2. User should be able to set disclosure as trade secret. | C27: NA | D27: =SYM_3.6_INV_8!K28 | E27: =SYM_3.6_INV_8!L28
A28: SYM_3.6_INV_9 | B28: 1. User should be able to combine another invention disclosure to this disclsoure. | C28: NA | D28: =SYM_3.6_INV_9!K16 | E28: =SYM_3.6_INV_9!L16

Sheet SYM_3.6_INV_1
A1: TEST CASE SPECIFICATION (Symphony IPM - v3.6)
A2: Test Title: | B2: Authorised user should be able to create and submit an invention disclosure. | I2: Test Case ID: | J2: SYM_3.6_INV_1
A3: Prepared by: | B3: Sowbarnika M | F3: Prepared On: | I3: Applicable Roles: | J3: Inventor
A4: Reviewed by: | F4: Reviewed On: | J4: IC
A5: Executed by: | F5: Executed On: | J5: Admin
A6: Descriptions: | B6: User should be able to create an invention disclosure, add the additional details such as notes, files and submit it. | I6: Test Scenarios: | J6: 1.User should be able to create a draft invention disclosure.
A7: Environment : | B7: Partial/Prod | F7: Browser Used: | J7: 2.User should be able to edit the invention disclosure.
A8: Pre-requisites: | B8: 1. User should permission to create and edit the invention disclosure. | J8: 3. User should be able to add and edit notes to the disclosure.
B9: 2. Keyword should be already added in the system. | J9: 4. User should be able to share the notes to an the disclosure.
J10: 5. User should be able to upload files to the disclosure.
J11: 6. User should be able to create Keywords for a disclosure.
J12: 7. User should be able to add and remove additional Inventors to the disclosure.
J13: 8. User should be able to Submit the invention disclosure.
J14: 9. User should be able to edit the some of the disclosure information after submitting it.
K18: Status Pass/Fail
A19: Step No. | B19: Steps to Execution/ Reproduce | F19: Expected Result | I19: Actual Result | K19: Inventor | L19: IC | M19: Admin | N19: Comments and Bug ID
A20: 1. User should be able to create a draft invention disclosure.
A21: 1.01 | B21: Log into Symphony with one of the applicable roles. | F21: User logs in successfully.
A22: 1.02 | B22: Select 'Invention Disclosures' menu and click 'New invention disclosure' option. | F22: New Invention disclosure page is displayed.
A23: 1.03 | B23: Enter a valid Invention Title. | F23: User is able to provide a valid Title.
A24: 1.04 | B24: Check if the Logged in user name is added under Inventor - Point of Contact | F24: Logged in user is prepopulated as the Inventor-Point of Contact.
A25: 1.05 | B25: Check if the Invention date is prepopulated with current date. | F25: The current date is prepopulated as the invention date.
A26: 1.06 | B26: Select a valid country for Jurisdiction. | F26: User is able to select a country value.
A27: 1.07 | B27: Enter valid information for details of the invention given under step 1 questions. | F27: User is able to provide the details to all the questions in step 1.
A28: 1.08 | B28: Enter valid information to all the additional Invention detail question provided under step 2. | F28: User is able to answer all the additional invention details questions in step 2. Note: If there are yes/no type question based on which values need to be entered. Only if condition in question is satisfied user should be able to provide the additional value.
A29: 1.09 | B29: Check if a Path is already prepopulated in Select a Path section. | F29: Path is prepopulated.
A30: 1.1 | B30: Search and add another inventor to this disclosure. Note: Only users with role Inventors should be available for user to choose from. | F30: User is able to search and add another user in Add Inventors section.
A31: 1.11 | B31: Select 'Upload Files' option to search and upload a file to this disclosure. Note: The file size should be within 10 MB. | F31: User is able to select a file and upload it.
A32: 1.12 | B32: Select 'Save as draft' option and click 'Next' to create the invention disclosure. | F32: 1. The new invention disclosure is created with provided information, 2. Internal Counsel is auto populated based on the Path provided 3. status as 'Draft'. 4. Email is sent to First Named inventor and any other inventors added.
A33: 2. User should be able to edit the invention disclosure.
A34: 2.01 | B34: Select the Invention Disclosures menu and navigate to that tab. | F34: List of all the disclosures recently viewed by user is listed here.
A35: 2.02 | B35: Find the Invention disclosure record created in previous section, click the down arrow on the right corner of the record and select 'Edit' option. | F35: User is able view the invention disclosure in a new window.
A36: 2.03 | B36: Check if the user is able to only edit the Docket Number and Parent Disclosure. | F36: User is only able to edit the Docket Number and Parent Disclosure. The rest are not editable.
A37: 2.04 | B37: Edit the docket number and click 'Save' | F37: The invention disclosure's docket number is updated.
A38: 3. User should be able to add and edit notes to the disclosure.
A39: 3.01 | B39: Select the 'Docket No.' of the invention disclosure created in previous section. | F39: User is able to view the invention disclosure detail page.
A40: 3.02 | B40: Scroll down to the Notes Card on the right side of the detail page. | F40: The Notes Card is visible to the user.
A41: 3.03 | B41: Click the arrow button on the right side of the card and select 'New' option. | F41: The details to create notes are displayed in a popup window. 'Related to' is set to the disclosure docket number by default.
A42: 3.04 | B42: Enter a Title for the note. | F42: User is able to enter a title.
A43: 3.05 | B43: Enter a description for the note. | F43: User is able to enter the description/detail.
...

Sheet SYM_3.6_INV_2
A1: TEST CASE SPECIFICATION (Symphony IPM - v3.6)
A2: Test Title: | B2: Authorised user should be able to print all invention disclosure and also reassign IC from the Invention Disclosure list . | I2: Test Case ID: | J2: SYM_3.6_INV_2
A3: Prepared by: | B3: Sowbarnika M | F3: Prepared On: | I3: Applicable Roles: | J3: Inventor
A4: Reviewed by: | F4: Reviewed On: | J4: IC
A5: Executed by: | F5: Executed On: | J5: Admin
A6: Descriptions: | B6: User should be able to View a Printable format of the all the invention disclosures accessible to them. User should be able to reassign IC to any invention disclosure from the list view. | I6: Test Scenarios: | J6: 1. User should be able to view the Printable view of all the Invention disclosures accessed by them.
A7: Environment : | B7: Partial/Prod | F7: Broswer Used: | J7: 2. User should be able to Reassign-IC to an Invention disclosure.
A8: Pre-requisites: | B8: 1. User should permission to view and edit the invention disclosure.
K12: Status Pass/Fail
A13: Step No. | B13: Steps to Execution/ Reproduce | F13: Expected Result | I13: Actual Result | K13: Inventor | L13: IC | M13: Admin | N13: Comments and Bug ID
A14: 1. User should be able to view the Printable view of all the Invention disclosures accessed by them.
A15: 1.01 | B15: Log into Symphony with one of the applicable roles. | F15: User logs in successfully.
A16: 1.02 | B16: Select the 'Invention Disclosures' menu. | F16: User is navigated to Invention Disclosures tab. List of invention disclosure recently viewed by logged in user is displayed.
A17: 1.03 | B17: Under 'Invention Disclosures' tab name change the filter option from 'Recently Viewed' to 'All'. | F17: System displays all the invention disclosures that is accessible by loggged in user.
A18: 1.04 | B18: Select 'Printable View' option displayed on the right side above the list of records. | F18: The list of invention disclosures are displayed in a new tab in Print view. Options to print this page and close is available.
A19: 1.05 | B19: Select 'Close window' option on the top right corner. | F19: The new tab with closed and user is returned to previous screen.
A20: 2. User should be able to Reassign-IC to an Invention disclosure.
A21: 2.01 | B21: Continued from previous section. Select 'Re-assign IC' option displayed on the right side above the list of records. | F21: System prompts the error 'select at least one record'
A22: 2.02 | B22: Select any invention disclosure by clicking the checkbox near its Docket No. note: while selecting multiple disclosure records make sure they are of same record type (i.e. same Status). | F22: User is able to select few invention disclosure records.
A23: 2.03 | B23: Select 'Re-assign IC' option. | F23: An popup to get the details to reassign IC is displayed.
A24: 2.04 | B24: In the Internal Counsel field, select another user (with IC role). | F24: The chosen user name is displayed in the field.
A25: 2.05 | B25: Click 'Save' option. | F25: System displayes the confirmation popup.
A26: 2.06 | B26: Select 'OK' option. | F26: The selected user is updated as the IC for the selected disclosure(s).

Sheet SYM_3.6_INV_3
A1: TEST CASE SPECIFICATION (Symphony IPM - v3.6)
A2: Test Title: | B2: Authorised user should be able to clone and delete invention disclosure. | I2: Test Case ID: | J2: SYM_3.6_INV_3
A3: Prepared by: | B3: Sowbarnika M | F3: Prepared On: | I3: Applicable Roles: | J3: IC
A4: Reviewed by: | F4: Reviewed On: | J4: Admin
A5: Executed by: | F5: Executed On:
A6: Descriptions: | B6: User should be able to clone and delete invention disclosure. | I6: Test Scenarios: | J6: 1. User should be able to clone an Invention disclosure.
A7: Environment: | B7: Partial/Prod | F7: Broswer Used: | J7: 2. User should be able to delete an Invention disclosure.
A8: Pre-requisites: | B8: 1. User should have permission to clone the invention disclosure.
B9: 2. User should have permission to delete the invention disclosure.
K12: Status Pass/Fail
A13: Step No. | B13: Steps to Execution/ Reproduce | F13: Expected Result | I13: Actual Result | K13: IC | L13: Admin | M13: Comments and Bug ID
A14: 1. User should be able to clone an Invention disclosure.
A15: 1.01 | B15: Log into Symphony with one of the applicable roles. | F15: User logs in successfully.
A16: 1.02 | B16: Select the 'Invention Disclosures' menu. | F16: User is navigated to Invention Disclosures tab. List of invention disclosures recently viewed by logged in user is displayed.
A17: 1.03 | B17: Select the 'Docket No.' of any of the invention disclosure. | F17: The selected invention disclosure's detail page is displayed.
A18: 1.04 | B18: Select the 'Clone' option on the top right corner of the detail page. | F18: A new invention disclosure page with all the details copied from selected disclosure is displayed.
A19: 1.05 | B19: Edit the title, invention date and provide invention details. | F19: User is able to edit/add information to the cloned disclosure.
A20: 1.06 | B20: Select 'Save' option. | F20: The New disclosure is created with same status as the cloned record.
A21: 2. User should be able to delete an Invention disclosure.
A22: 2.01 | B22: Select the Invention Disclosures menu and navigate to that tab. | F22: List of all the disclosures recently viewed by user is listed here.
A23: 2.02 | B23: Select a invention disclosure record and click the down arrow on the right corner of the record and select 'Delete' option. Note: The status of the disclosure record should be 'Draft'. | F23: A confirmation popup is displayed to the user.
A24: 2.03 | B24: Select 'Delete' option on the Confirmation popup box. | F24: The selected invention disclosure id deleted and system displays as success message.

Sheet SYM_3.6_INV_4
A1: TEST CASE SPECIFICATION (Symphony IPM - v3.6)
A2: Test Title: | B2: Authorized user should be able to view the invention disclosure submitted to them, create PRC Meeting and Approve them. | I2: Test Case ID: | J2: SYM_3.6_INV_4
A3: Prepared by: | B3: Sowbarnika M | F3: Prepared On: | I3: Applicable Roles: | J3: IC
A4: Reviewed by: | F4: Reviewed On: | J4: Admin
A5: Executed by: | F5: Executed On:
A6: Descriptions: | B6: User is able to review the invention disclosure submitted to them, create PRC meeting and approve them. | I6: Test Scenarios: | J6: 1. User should be able to view the invention disclosures created in the Path associated to them.
A7: Environment: | B7: Partial/Prod | F7: Broswer Used: | J7: 2. User should be able to create a PRC Meeting for the invention disclosure.
A8: Pre-requisites: | B8: 1. User is authorized to edit the disclosure and perform the action on it. | J8: 3. User should be able to approve the information disclosure.
B9: 2. Information disclosure record is already created and submitted by Inventor. | J9: 4. User should be able to approve and send the disclosure to OC .
B10: 3. User is set as the In-house Counsel for the invention disclosure. | J10: 5. User should be able to set disclosure to International Filing Decision.
K14: Status Pass/Fail
A15: Step No. | B15: Steps to Execution/ Reproduce | F15: Expected Result | I15: Actual Result | K15: IC | L15: Admin | M15: Comments and Bug ID
A16: 1. User should be able to view the invention disclosures created in the Path associated to them.
A17: 1.01 | B17: Log into Symphony with one of the applicable roles. | F17: User logs in successfully.
A18: 1.02 | B18: Select the 'Invention Disclosures' menu. | F18: User is navigated to Invention Disclosures tab. List of invention disclosures recently viewed by logged in user is displayed.
A19: 1.03 | B19: Under 'Invention Disclosures' tab name change the filter option from 'Recently Viewed' to 'All'. | F19: System displays all the invention disclosures that is assigned to the path associated to the logged in user.
A20: 2. User should be able to create and delete a PRC Meeting for the invention disclosure.
A21: 2.01 | B21: Select the 'Docket No.' of any submitted invention disclosure. | F21: The selected invention disclosure's detail page is displayed.
A22: 2.02 | B22: Scroll to the 'Add to PRC Meeting' card on the right of the disclosure's detail page. | F22: Add to PRC Meeting' card is visible to the user. By default 'Create new PRC Meeting' option is selected in the drop down.
A23: 2.03 | B23: Select 'next' option. | F23: The details required to a new meeting is prompted to the user in the same card.
A24: 2.04 | B24: Select a appropriate date for 'Meeting Date'. | F24: User is able to select a valid date.
A25: 2.05 | B25: Enter a valid 'Meeting Start Time'. Note: follow 24 hour format while mentioning the time. | F25: User is able to enter a valid Meeting start time.
A26: 2.06 | B26: Enter the duration in minutes in 'Meeting duration'. | F26: User is able to enter a valid Meeting duration.
A27: 2.07 | B27: Enter a valid 'Meeting Location'. | F27: User is able to enter a valid Meeting location.
A28: 2.08 | B28: Select 'next' option. | F28: The PRC Meeting with the provided details is created.
A29: 2.09 | B29: Select 'Next' option in the Add to PRC Meeting card where the newly created meeting is displayed. | F29: The PRC Meeting is deleted.
A30: 3. User should be able to approve the information disclosure.
A31: 3.01 | B31: Continued from previous section. Scroll to the 'Disclosure Review' Card on the right side of the disclosure detail page. | F31: Disclosure Review card is visible to the user.
A32: 3.02 | B32: Select 'Approve' action. | F32: User is able to select the action.
A33: 3.03 | B33: Select 'Next' option. | F33: System prompts the user to enter the case ratings.
A34: 3.04 | B34: Enter valid information for Detection Ease, Claim Value, Internal Value, Competitive Value. | F34: User is able to provide valid information for the mentioned fields.
A35: 3.05 | B35: In the Case Details section, First Filing Jurisdiction is prepopulated with the country selected as the jurisdiction of the given disclosure. | F35: Jurisdiction country is pre-populated as the First filing jurisdiction.
A36: 3.06 | B36: Select a suitable Filing Type. By Default 'Provisional' value should be selected. | F36: Provisional' value is auto-populated in Filing Type.
A37: 3.07 | B37: Click 'Next' option | F37: The information 'This Disclosure is approved and the patent shell record can be accessed here.' is displayed in the Disclosure Review tab. The corresponding Patent record is created for this invention disclosure.
A38: 3.08 | B38: Click 'Here' link in the Disclosure Tab. | F38: The created Patent record detail is displayed in a new tab. Title, Internal Counsel, Jurisdiction, First Named Inventor, Inventors are copied from the disclosure record. Base Invention Disclosure is populated with the docket number of the approved disclosure record.
A39: 3.09 | B39: Close the new tab. | F39: User is able to view the disclosure record in previous tab.
A40: 3.1 | B40: In the Disclosure Review Card, select 'Next'. | F40: The status of the disclosure is updated as 'Closed Approved for filing'.
A41: 4. User should be able to approve and send the disclosure to OC .
A42: 4.01 | B42: Select the 'Invention Disclosures' menu. | F42: User is navigated to Invention Disclosures tab. List of invention disclosures recently viewed by logged in user is displayed.
A43: 4.02 | B43: Select the 'Docket No.' of any submitted invention disclosure. | F43: The selected invention disclosure's detail page is displayed.
...

Sheet SYM_3.6_INV_5
A1: TEST CASE SPECIFICATION (Symphony IPM - v3.6)
A2: Test Title: | B2: Authorized IC user should be able to request for more information about the invention disclosure from the inventor and they should respond to it. | I2: Test Case ID: | J2: SYM_3.6_INV_5
A3: Prepared by: | B3: Sowbarnika M | F3: Prepared On: | I3: Applicable Roles: | J3: IC (scenario 1)
A4: Reviewed by: | F4: Reviewed On: | J4: Inventor (scenario 2)
A5: Executed by: | F5: Executed On:
A6: Descriptions: | B6: IC user associated to the invention disclosure should be able to request for more information from the inventor. Inventor should notified of this request and should be able to provide the information to the IC. | I6: Test Scenarios: | J6: 1. IC User should be able to request for more information to the inventor.
A7: Environment: | B7: Partial/Prod | F7: Broswer Used: | J7: 2. Inventor should be able to respond to the RFI.
A8: Pre-requisites: | B8: 1. User is authorized to edit the disclosure and perform the action on it.
B9: 2. Few Information disclosure records are already created and submitted by Inventor.
B10: 3. User is set as the In-house Counsel for the invention disclosure.
K14: Status Pass/Fail
A15: Step No. | B15: Steps to Execution/ Reproduce | F15: Expected Result | I15: Actual Result | K15: IC | L15: Inventor | M15: Comments and Bug ID
A16: 1. IC User should be able to request for more information to the inventor. | L16: NA
A17: 1.01 | B17: Log into Symphony as a user with IC role. | F17: User logs in successfully.
A18: 1.02 | B18: Select the 'Invention Disclosures' menu. | F18: User is navigated to Invention Disclosures tab. List of invention disclosures recently viewed by logged in user is displayed.
A19: 1.03 | B19: Select the 'Docket No.' of any submitted invention disclosure. | F19: The selected invention disclosure's detail page is displayed.
A20: 1.04 | B20: Scroll to the 'Disclosure Review' Card on the right side of the disclosure detail page. | F20: Disclosure Review card is visible to the user.
A21: 1.05 | B21: Select 'Request More Information' action. | F21: User is able to select the action.
A22: 1.06 | B22: Select 'Next' option. | F22: System prompts the user to enter his questions.
A23: 1.07 | B23: Enter valid information in the 'Your Questions' box. | F23: User is able to enter the question.
A24: 1.08 | B24: Select 'Next' option. | F24: The Disclosure Status is updated to 'Need More Information'. Email notification on the status update is sent to the First Named Inventor.
A25: 2. Inventor should be able to respond to the RFI. | K25: NA
A26: 2.01 | B26: Log into Symphony as a user with Inventor role. Note: the user should be the First Named Inventor of the disclosure used in previous section. | F26: User logs in successfully.
A27: 2.02 | B27: Select the 'Invention Disclosures' menu. | F27: User is navigated to Invention Disclosures tab. List of invention disclosures recently viewed by logged in user is displayed.
A28: 2.03 | B28: Select the 'Docket No.' of invention disclosure with status 'Need more Information' that was used in previous section. | F28: The selected invention disclosure's detail page is displayed.
A29: 2.04 | B29: Scroll to the 'Respond to RFI' Card on the right side of the disclosure detail page. | F29: Respond to RFI card is visible to the user.
A30: 2.05 | B30: Select 'Next' option. | F30: System prompts the user to enter the response in the same card.
A31: 2.06 | B31: Enter a valid response. | F31: User is able to enter the response.
A32: 2.07 | B32: Select 'Next' option. | F32: Disclosure status is updated to 'Submitted' and email notification is sent to the IC.

Sheet SYM_3.6_INV_6
A1: TEST CASE SPECIFICATION (Symphony IPM - v3.6)
A2: Test Title: | B2: Authorized user should be able to request for patent search for the given invention disclosure. | I2: Test Case ID: | J2: SYM_3.6_INV_6
A3: Prepared by: | B3: Sowbarnika M | F3: Prepared On: | I3: Applicable Roles: | J3: IC
A4: Reviewed by: | F4: Reviewed On: | J4: Admin
A5: Executed by: | F5: Executed On:
A6: Descriptions: | B6: User should be able to request for patent search for the given invention disclosure. | I6: Test Scenarios: | J6: 1. User should be able to request for patent search for the disclosure.
A7: Environment: | B7: Partial/Prod | F7: Broswer Used:
A8: Pre-requisites: | B8: 1. User is authorized to edit the disclosure and perform the action on it.
B9: 2. Few Information disclosure records are already created and submitted by Inventor.
B10: 3. User is set as the In-house Counsel for the invention disclosure.
K14: Status Pass/Fail
A15: Step No. | B15: Steps to Execution/ Reproduce | F15: Expected Result | I15: Actual Result | K15: IC | L15: Admin | M15: Comments and Bug ID
A16: 1. User should be able to request patent search for the disclosure.
A17: 1.01 | B17: Log into Symphony with one of the applicable roles. | F17: User logs in successfully.
A18: 1.02 | B18: Select the 'Invention Disclosures' menu. | F18: User is navigated to Invention Disclosures tab. List of invention disclosures recently viewed by logged in user is displayed.
A19: 1.03 | B19: Select the 'Docket No.' of any submitted invention disclosure. | F19: The selected invention disclosure's detail page is displayed.
A20: 1.04 | B20: Scroll to the 'Disclosure Review' Card on the right side of the disclosure detail page. | F20: Disclosure Review card is visible to the user.
A21: 1.05 | B21: Select 'Request Patent Search' action. | F21: User is able to select the action.
A22: 1.06 | B22: Select 'Next' option. | F22: System prompts the user to enter the comments and select the search firm and OC.
A23: 1.07 | B23: Enter some valid comments in the 'Comments' section. | F23: User is able to provide comments.
A24: 1.08 | B24: Select a law firm in 'Select Search firm' field. | F24: User is able to select a law firm. The OC associated to law firm are displayed in the 'Select Outside Counsel' field.
A25: 1.09 | B25: Select one of the user associasted to the law firm as the outside counsel. | F25: user is able to select a user from the list.
A26: 1.1 | B26: Click 'Next' option | F26: 1. The Disclosure status should be changed to "Request Patent Search" and patent shell record should not be created. 2. Email notification is sent to OC.

Sheet SYM_3.6_INV_7
A1: TEST CASE SPECIFICATION (Symphony IPM - v3.6)
A2: Test Title: | B2: Authorised user should be able to hold or reject an invention disclosure. | I2: Test Case ID: | J2: SYM_3.6_INV_7
A3: Prepared by: | B3: Sowbarnika M | F3: Prepared On: | I3: Applicable Roles: | J3: IC
A4: Reviewed by: | F4: Reviewed On: | J4: Admin
A5: Executed by: | F5: Executed On:
A6: Descriptions: | B6: User should be able to hold or reject an invention disclosure. | I6: Test Scenarios: | J6: 1. User should be able to set the disclosure status as Hold.
A7: Environment: | B7: Partial/Prod | F7: Broswer Used: | J7: 2. User should be able to set the disclosure status as Reject.
A8: Pre-requisites: | B8: 1. User is authorized to edit the disclosure and perform the action on it.
B9: 2. Few Information disclosure records are already created and submitted by Inventor.
B10: 3. User is set as the In-house Counsel for the invention disclosure.
K14: Status Pass/Fail
A15: Step No. | B15: Steps to Execution/ Reproduce | F15: Expected Result | I15: Actual Result | K15: IC | L15: Admin | M15: Comments and Bug ID
A16: 1. User should be able to set the disclosure status as Hold.
A17: 1.01 | B17: Log into Symphony with one of the applicable roles. | F17: User logs in successfully.
A18: 1.02 | B18: Select the 'Invention Disclosures' menu. | F18: User is navigated to Invention Disclosures tab. List of invention disclosures recently viewed by logged in user is displayed.
A19: 1.03 | B19: Select the 'Docket No.' of any submitted invention disclosure. | F19: The selected invention disclosure's detail page is displayed.
A20: 1.04 | B20: Scroll to the 'Disclosure Review' Card on the right side of the disclosure detail page. | F20: Disclosure Review card is visible to the user.
A21: 1.05 | B21: Select 'Hold' action. | F21: User is able to select the action.
A22: 1.06 | B22: Select 'Next' option. | F22: System prompts the user to enter the comments.
A23: 1.07 | B23: Enter some valid comments in the 'Comments' section. | F23: User is able to provide comments.
A24: 1.08 | B24: Select 'Next' option. | F24: Disclosure status is updated to 'Hold'.
A25: 2. User should be able to set the disclosure status as Reject.
A26: 2.01 | B26: Select the 'Invention Disclosures' menu. | F26: User is navigated to Invention Disclosures tab. List of invention disclosures recently viewed by logged in user is displayed.
A27: 2.02 | B27: Select the 'Docket No.' of any submitted invention disclosure. | F27: The selected invention disclosure's detail page is displayed.
A28: 2.03 | B28: Scroll to the 'Disclosure Review' Card on the right side of the disclosure detail page. | F28: Disclosure Review card is visible to the user.
A29: 2.04 | B29: Select 'Reject' action. | F29: User is able to select the action.
A30: 2.05 | B30: Select 'Next' option. | F30: System prompts the user to enter the comments.
A31: 2.06 | B31: Enter some valid comments in the 'Comments' section. | F31: User is able to provide comments.
A32: 2.07 | B32: Select 'Next' option. | F32: Disclosure status is updated to 'Closed - Rejected'.

Sheet SYM_3.6_INV_8
A1: TEST CASE SPECIFICATION (Symphony IPM - v3.6)
A2: Test Title: | B2: Authorised user should be able to close the disclosure by setting it as defensive publication or Trade secret. | I2: Test Case ID: | J2: SYM_3.6_INV_8
A3: Prepared by: | B3: Sowbarnika M | F3: Prepared On: | I3: Applicable Roles: | J3: IC
A4: Reviewed by: | F4: Reviewed On: | J4: Admin
A5: Executed by: | F5: Executed On:
A6: Descriptions: | I6: Test Scenarios: | J6: 1. User should be able to set disclosure as defensive publication.
A7: Environment: | B7: Partial/Prod | F7: Broswer Used: | J7: 2. User should be able to set disclosure as trade secret.
A8: Pre-requisites: | B8: 1. User is authorized to edit the disclosure and perform the action on it.
B9: 2. Few Information disclosure records are already created and submitted by Inventor.
B10: 3. User is set as the In-house Counsel for the invention disclosure.
K14: Status Pass/Fail
A15: Step No. | B15: Steps to Execution/ Reproduce | F15: Expected Result | I15: Actual Result | K15: IC | L15: Admin | M15: Comments and Bug ID
A16: 1. User should be able to set disclosure as defensive publication.
A17: 1.01 | B17: Log into Symphony with one of the applicable roles. | F17: User logs in successfully.
A18: 1.02 | B18: Select the 'Invention Disclosures' menu. | F18: User is navigated to Invention Disclosures tab. List of invention disclosures recently viewed by logged in user is displayed.
A19: 1.03 | B19: Select the 'Docket No.' of any submitted invention disclosure. | F19: The selected invention disclosure's detail page is displayed.
A20: 1.04 | B20: Scroll to the 'Disclosure Review' Card on the right side of the disclosure detail page. | F20: Disclosure Review card is visible to the user.
A21: 1.05 | B21: Select 'Defensive Publication' action. | F21: User is able to select the action.
A22: 1.06 | B22: Select 'Next' option. | F22: System prompts the user to enter the case ratings.
A23: 1.07 | B23: Enter valid information for Detection Ease, Claim Value, Internal Value, Competitive Value. | F23: User is able to provide valid information for the mentioned fields.
A24: 1.08 | B24: Provide valid 'Instruction for Outside Counsel' and Select a 'Target Filing Date'. | F24: User is able to provide valid information for the mentioned fields.
A25: 1.09 | B25: Select a law firm in 'Select Law firm' field. | F25: User is able to select a law firm. The OC associated to law firm are displayed in the 'Select Outside Counsel' field.
A26: 1.1 | B26: Select one of the user associasted to the law firm as the outside counsel. | F26: user is able to select a user from the list.
A27: 1.11 | B27: Click 'Next' option | F27: The Disclosure status is updated as "Closed - Defensive Publication" and a patent shell record is created.
A28: 2. User should be able to set disclosure as trade secret.
A29: 2.01 | B29: Log into Symphony with one of the applicable roles. | F29: User logs in successfully.
A30: 2.02 | B30: Select the 'Invention Disclosures' menu. | F30: User is navigated to Invention Disclosures tab. List of invention disclosures recently viewed by logged in user is displayed.
A31: 2.03 | B31: Select the 'Docket No.' of any submitted invention disclosure. | F31: The selected invention disclosure's detail page is displayed.
A32: 2.04 | B32: Scroll to the 'Disclosure Review' Card on the right side of the disclosure detail page. | F32: Disclosure Review card is visible to the user.
A33: 2.05 | B33: Select 'Trade Secret' action. | F33: User is able to select the action.
A34: 2.06 | B34: Select 'Next' option. | F34: System prompts the user to enter the comments.
A35: 2.07 | B35: Enter some valid comments in the 'Comments' section. | F35: User is able to provide comments.
A36: 2.08 | B36: Click 'Next' option | F36: The Disclosure status is updated as "Closed - Trade Secret" and patent shell record is not created.

Sheet SYM_3.6_INV_9
A1: TEST CASE SPECIFICATION (Symphony IPM - v3.6)
A2: Test Title: | B2: Authorized user should be able to combine another invention disclosure to this disclsoure. | I2: Test Case ID: | J2: SYM_3.6_INV_9
A3: Prepared by: | B3: Sowbarnika M | F3: Prepared On: | I3: Applicable Roles: | J3: IC
A4: Reviewed by: | F4: Reviewed On: | J4: Admin
A5: Executed by: | F5: Executed On:
A6: Descriptions: | B6: User should be able to combine another invention disclosure to this disclsoure. | I6: Test Scenarios: | J6: 1. User should be able to combine another invention disclosure to this disclsoure.
A7: Environment: | B7: Partial/Prod | F7: Broswer Used:
A8: Pre-requisites: | B8: 1. User is authorized to edit the disclosure and perform the action on it.
B9: 2. Few Information disclosure records are already created and submitted by Inventor.
B10: 3. User is set as the In-house Counsel for the invention disclosure.
K14: Status Pass/Fail
A15: Step No. | B15: Steps to Execution/ Reproduce | F15: Expected Result | I15: Actual Result | K15: IC | L15: Admin | M15: Comments and Bug ID
A16: 1. User should be able to combine another invention disclosure to this disclsoure.
A17: 1.01 | B17: Log into Symphony with one of the applicable roles. | F17: User logs in successfully.
A18: 1.02 | B18: Select the 'Invention Disclosures' menu. | F18: User is navigated to Invention Disclosures tab. List of invention disclosures recently viewed by logged in user is displayed.
A19: 1.03 | B19: Select the 'Docket No.' of any submitted invention disclosure. | F19: The selected invention disclosure's detail page is displayed.
A20: 1.04 | B20: Scroll to the 'Disclosure Review' Card on the right side of the disclosure detail page. | F20: Disclosure Review card is visible to the user.
A21: 1.05 | B21: Select 'Combine' action. | F21: User is able to select the action.
A22: 1.06 | B22: Select 'Next' option. | F22: System prompts the user to search and select a parent disclosure.
A23: 1.07 | B23: Search and Select the Docket number of the desired invention disclosure. Note: type SYM to see the various docket numbers. | F23: User is able to search and select an invension disclosure.
A24: 1.08 | B24: Select 'Next' option. | F24: The Disclosure Status is updated as 'Merged' and the selected disclosure's docket number is saved under Parent Disclosure field in Related Records section.
